<?xml version="1.0" ?>
<!-- =================================================================================== -->
<!-- |    This document was autogenerated by xacro from wsn_both_psms.urdf.xacro       | -->
<!-- |    EDITING THIS FILE BY HAND IS NOT RECOMMENDED                                 | -->
<!-- =================================================================================== -->
<robot name="dvrk_psm" xmlns:xacro="http://www.ros.org/wiki/xacro">
  <material name="DaVinciWhite">
    <color rgba="1.0 1.0 1.0 1"/>
  </material>
  <material name="DaVinciLightGray">
    <color rgba="0.8 0.8 0.8 1"/>
  </material>
  <material name="DaVinciMedGray">
    <color rgba="0.6 0.6 0.6 1"/>
  </material>
  <material name="DaVinciDarkGray">
    <color rgba="0.4 0.4 0.4 1"/>
  </material>
  <material name="DaVinciRed">
    <color rgba="0.5 0.4 0.4 1"/>
  </material>
  <material name="DaVinciGreen">
    <color rgba="0.4 0.5 0.4 1"/>
  </material>
  <material name="DaVinciBlue">
    <color rgba="0.4 0.4 0.5 1"/>
  </material>
  <material name="GazeboRed">
    <color rgba="1 0 0 1"/>
  </material>
  <!--xacro:include filename="$(find dvrk_model)/model/psm.tool.caudier.urdf.xacro"/-->
  <link name="world">
    <origin xyz="0.0 0.0 0.0"/>
  </link>
  <joint name="world_joint" type="fixed">
    <parent link="world"/>
    <child link="camera"/>
    <origin rpy="0.0 0.0 0.0" xyz="0.0 0.0 0.4"/>
  </joint>
  <link name="camera">
    <origin rpy="0.0 0.0 0.0" xyz="0.0 0.0 0.8"/>
  </link>
  <joint name="camera_joint" type="fixed">
    <parent link="camera"/>
    <child link="right_camera_link"/>
    <origin rpy="0.0 1.5708 1.5708" xyz="-0.005 0.0 0.5"/>
  </joint>
  <link name="right_camera_link">
    <visual>
      <origin rpy="0 0 0" xyz="0 0 0.0"/>
      <geometry>
        <box size="0.03 0.01 0.01"/>
      </geometry>
      <material name="red"/>
    </visual>
    <inertial>
      <mass value="1e-5"/>
      <origin rpy="0 0 0" xyz="0 0 0"/>
      <inertia ixx="1e-6" ixy="0" ixz="0" iyy="1e-6" iyz="0" izz="1e-6"/>
    </inertial>
    <!--origin rpy="0.0 0.0 0.0" xyz="0.0 0.2 0.8"/-->
  </link>
  <joint name="left_camera_joint" type="fixed">
    <parent link="camera"/>
    <child link="left_camera_link"/>
    <origin rpy="0.0 1.5708 1.5708" xyz="0.005 0.00 0.5"/>
  </joint>
  <link name="left_camera_link">
    <visual>
      <origin rpy="0 0 0" xyz="0 0 0.0"/>
      <geometry>
        <box size="0.03 0.01 0.01"/>
      </geometry>
      <material name="red"/>
    </visual>
    <inertial>
      <mass value="1e-5"/>
      <origin rpy="0 0 0" xyz="0 0 0"/>
      <inertia ixx="1e-6" ixy="0" ixz="0" iyy="1e-6" iyz="0" izz="1e-6"/>
    </inertial>
    <!--origin rpy="0.0 0.0 0.0" xyz="0.0 0.2 0.8"/-->
  </link>
  <!-- fixed joint -->
  <joint name="one_fixed_joint" type="fixed">
    <parent link="camera"/>
    <child link="one_psm_base_link"/>
    <origin rpy="0.0 0.0 3.1415926" xyz="-0.15 0.05 0.5"/>
  </joint>
  <!-- link 0: psm base link -->
  <link name="one_psm_base_link">
    <visual>
      <origin rpy="1.5708 0 3.1416" xyz="0.039 -0.40788 -0.07879"/>
      <geometry>
        <mesh filename="package://dvrk_model/meshes/psm/psm_base.dae"/>
      </geometry>
    </visual>
    <inertial>
      <origin rpy="0 0 0" xyz="0 0 0"/>
      <mass value="1"/>
      <inertia ixx="0.1" ixy="0.0" ixz="0.0" iyy="0.1" iyz="0.0" izz="0.1"/>
    </inertial>
  </link>
  <!-- joint 1 -->
  <joint name="one_outer_yaw_joint" type="revolute">
    <parent link="one_psm_base_link"/>
    <child link="one_outer_yaw_link"/>
    <axis xyz="0 0 1"/>
    <!-- <origin rpy="1.5708 -1.5708 0" xyz="0.0 -0.369 0.0"/> -->
    <origin rpy="0 -1.5708 1.5708" xyz="0.0 0.0 0.0"/>
    <dynamics damping="1"/>
    <limit effort="1000" lower="-1.5707" upper="1.5707" velocity=".4"/>
  </joint>
  <!-- link 1: outer_yaw -->
  <link name="one_outer_yaw_link">
    <visual>
      <!-- <origin rpy="0 0 -1.5708" xyz="0.0125 0 0.1575"/> -->
      <origin rpy="3.1416 0 1.5708" xyz="0.0125 0 0.5265"/>
      <geometry>
        <mesh filename="package://dvrk_model/meshes/psm/outer_yaw.dae"/>
      </geometry>
    </visual>
    <inertial>
      <origin rpy="0 0 0" xyz="0 0 0"/>
      <mass value="0.1"/>
      <inertia ixx="0.1" ixy="0.0" ixz="0.0" iyy="0.1" iyz="0.0" izz="0.005"/>
    </inertial>
  </link>
  <!-- Note: I can not put visual link here as it's parallel -->
  <!-- mechanism, so the outer_pitch_link does not have visual -->
  <!-- link, all visual links mimic outer_pitch_joint value -->
  <!-- joint 2: outer_pitch -->
  <joint name="one_outer_pitch_joint" type="revolute">
    <parent link="one_outer_yaw_link"/>
    <child link="one_outer_pitch_link"/>
    <axis xyz="0 0 1"/>
    <origin rpy="-1.5708 -1.5708 0" xyz="0 0 0"/>
    <dynamics damping="1"/>
    <limit effort="1000" lower="-0.7854" upper="0.7854" velocity=".4"/>
  </joint>
  <!-- link 2: outer_pitch_link -->
  <link name="one_outer_pitch_link">
    <inertial>
      <origin rpy="0 0 0" xyz="0 0 0"/>
      <mass value="0.1"/>
      <inertia ixx="0.1" ixy="0.0" ixz="0.0" iyy="0.1" iyz="0.0" izz="0.005"/>
    </inertial>
  </link>
  <!--wsn: for visualization links/joints of closed-chain mechanism, assign dynamic properties and control w/ fdbk-->
  <!-- joint 2-1: outer_pitch_1 -->
  <joint name="one_outer_pitch_joint_1" type="continuous">
    <parent link="one_outer_yaw_link"/>
    <child link="one_outer_pitch_back_link"/>
    <axis xyz="0 0 1"/>
    <!-- <origin rpy="-1.5708 -1.5708 0" xyz="0 0.0295 0.1495"/> -->
    <dynamics damping="1"/>
    <origin rpy="-1.5708 -1.5708 0" xyz="0 0.0295 0.5185"/>
    <!--mimic joint="${prefix}outer_pitch_joint" multiplier="1"/-->
    <limit effort="1000" lower="-0.7854" upper="0.7854" velocity=".4"/>
  </joint>
  <!-- link 2-1: outer_pitch_back -->
  <link name="one_outer_pitch_back_link">
    <visual>
      <origin rpy="0 0 -0.27129" xyz="0 0 0"/>
      <geometry>
        <mesh filename="package://dvrk_model/meshes/psm/outer_pitch_back.dae"/>
      </geometry>
    </visual>
    <inertial>
      <origin rpy="0 0 0" xyz="0 0 0"/>
      <mass value="0.1"/>
      <inertia ixx="0.1" ixy="0.0" ixz="0.0" iyy="0.1" iyz="0.0" izz="0.005"/>
    </inertial>
  </link>
  <!-- joint 2-2: outer_pitch_2 -->
  <joint name="one_outer_pitch_joint_2" type="continuous">
    <parent link="one_outer_yaw_link"/>
    <child link="one_outer_pitch_front_link"/>
    <axis xyz="0 0 1"/>
    <origin rpy="-1.5708 -1.5708 0" xyz="0 0.0295 0.4285"/>
    <!--mimic joint="${prefix}outer_pitch_joint" multiplier="1"/-->
    <limit effort="1000" lower="-0.7854" upper="0.7854" velocity=".4"/>
    <dynamics damping="1"/>
  </joint>
  <!-- link 2-2: outer_pitch_front -->
  <link name="one_outer_pitch_front_link">
    <visual>
      <origin rpy="0 0 -0.27129" xyz="0 0 0"/>
      <geometry>
        <mesh filename="package://dvrk_model/meshes/psm/outer_pitch_front.dae"/>
      </geometry>
    </visual>
    <inertial>
      <origin rpy="0 0 0" xyz="0 0 0"/>
      <mass value="0.1"/>
      <inertia ixx="0.1" ixy="0.0" ixz="0.0" iyy="0.1" iyz="0.0" izz="0.005"/>
    </inertial>
  </link>
  <!-- joint 2-3: outer_pitch_3 -->
  <joint name="one_outer_pitch_joint_3" type="continuous">
    <parent link="one_outer_pitch_back_link"/>
    <child link="one_outer_pitch_bottom_link"/>
    <axis xyz="0 0 1"/>
    <origin rpy="0 0 0" xyz="0.04178 0.15007 -0.0137"/>
    <origin rpy="0 0 0" xyz="0.04178 0.15007 -0.0137"/>
    <!--mimic joint="outer_pitch_joint" multiplier="-1"/-->
    <dynamics damping="1"/>
  </joint>
  <!-- link 2-3: outer_pitch_bottom -->
  <link name="one_outer_pitch_bottom_link">
    <visual>
      <origin rpy="0 -1.5708 0" xyz="0.009 0 0"/>
      <geometry>
        <mesh filename="package://dvrk_model/meshes/psm/outer_pitch_bottom.dae"/>
      </geometry>
    </visual>
    <inertial>
      <origin rpy="0 0 0" xyz="0 0 0"/>
      <mass value="0.1"/>
      <inertia ixx="0.1" ixy="0.0" ixz="0.0" iyy="0.1" iyz="0.0" izz="0.005"/>
    </inertial>
  </link>
  <!-- joint 2-4: outer_pitch_4 -->
  <joint name="one_outer_pitch_joint_4" type="continuous">
    <parent link="one_outer_pitch_back_link"/>
    <child link="one_outer_pitch_top_link"/>
    <axis xyz="0 0 1"/>
    <origin rpy="0 0 0" xyz="0.04209 0.18695 -0.02412"/>
    <!--mimic joint="${prefix}outer_pitch_joint" multiplier="-1"/-->
    <limit effort="1000" lower="-0.7854" upper="0.7854" velocity=".4"/>
    <dynamics damping="1"/>
  </joint>
  <!-- link 2-4: outer_pitch_top -->
  <link name="one_outer_pitch_top_link">
    <visual>
      <origin rpy="0 -1.5708 0" xyz="0.009 0 0"/>
      <geometry>
        <mesh filename="package://dvrk_model/meshes/psm/outer_pitch_top.dae"/>
      </geometry>
    </visual>
    <inertial>
      <origin rpy="0 0 0" xyz="0 0 0"/>
      <mass value="0.1"/>
      <inertia ixx="0.1" ixy="0.0" ixz="0.0" iyy="0.1" iyz="0.0" izz="0.005"/>
    </inertial>
  </link>
  <!-- joint 2-5: outer_pitch_5 -->
  <joint name="one_outer_pitch_joint_5" type="continuous">
    <parent link="one_outer_pitch_bottom_link"/>
    <child link="one_outer_insertion_link"/>
    <axis xyz="0 0 1"/>
    <origin rpy="0 0 0" xyz="-0.520 0 -0.0155"/>
    <!--mimic joint="${prefix}outer_pitch_joint" multiplier="1"/-->
    <limit effort="1000" lower="-0.7854" upper="0.7854" velocity=".4"/>
    <dynamics damping="1"/>
  </joint>
  <!-- link 2-5: outer_insertion -->
  <link name="one_outer_insertion_link">
    <visual>
      <origin rpy="0 -1.5708 1.5708" xyz="0.02528 0.429 0"/>
      <geometry>
        <mesh filename="package://dvrk_model/meshes/psm/outer_insertion.dae"/>
      </geometry>
    </visual>
    <inertial>
      <origin rpy="0 0 0" xyz="0 0 0"/>
      <mass value="0.1"/>
      <inertia ixx="0.1" ixy="0.0" ixz="0.0" iyy="0.1" iyz="0.0" izz="0.005"/>
    </inertial>
  </link>
  <!-- joint 3: insertion -->
  <joint name="one_outer_insertion_joint" type="prismatic">
    <!-- <parent link="${prefix}outer_insertion_link"/> -->
    <!-- <parent link="${prefix}psm_base_link"/> -->
    <parent link="one_outer_pitch_link"/>
    <child link="one_tool_main_link"/>
    <axis xyz="0 0 1"/>
    <origin rpy="1.5708 0 0" xyz="0 0.4318 0"/>
    <limit effort="1000" lower="0" upper="0.240" velocity=".4"/>
    <dynamics damping="1"/>
  </joint>
  <!-- link 3: tool_main_link -->
  <link name="one_tool_main_link">
    <visual>
      <origin rpy="0 0 1.5708" xyz="0 0 0.041"/>
      <geometry>
        <mesh filename="package://dvrk_model/meshes/psm/tool_main.dae"/>
      </geometry>
    </visual>
    <inertial>
      <origin rpy="0 0 0" xyz="0 0 0"/>
      <mass value="0.1"/>
      <inertia ixx="0.1" ixy="0.0" ixz="0.0" iyy="0.1" iyz="0.0" izz="0.005"/>
    </inertial>
  </link>
  <!-- joint 4: Outer Roll -->
  <joint name="one_outer_roll_joint" type="revolute">
    <parent link="one_tool_main_link"/>
    <child link="one_tool_wrist_link"/>
    <axis xyz="0 0 1"/>
    <origin rpy="0 0 0" xyz="0 0 0.4162"/>
    <limit effort="1000" lower="-2.2689" upper="2.2689" velocity=".4"/>
    <dynamics damping="1"/>
  </joint>
  <!-- link 4: tool_wrist_link -->
  <link name="one_tool_wrist_link">
    <visual>
      <origin rpy="0 0 1.5708" xyz="0 0 -0.0091"/>
      <geometry>
        <mesh filename="package://dvrk_model/meshes/psm/tool_wrist_link.dae"/>
      </geometry>
    </visual>
    <inertial>
      <origin rpy="0 0 0" xyz="0 0 0"/>
      <mass value="0.1"/>
      <inertia ixx="0.1" ixy="0.0" ixz="0.0" iyy="0.1" iyz="0.0" izz="0.005"/>
    </inertial>
  </link>
  <!-- joint 4-1: outer roll shaft joint FIXED-->
  <joint name="one_outer_roll_shaft_joint" type="fixed">
    <parent link="one_tool_wrist_link"/>
    <child link="one_tool_wrist_shaft_link"/>
    <axis xyz="0 0 1"/>
    <origin rpy="0 0 0" xyz="0 0 0.0"/>
  </joint>
  <!-- link 4-1: tool_wrist_shaft_link -->
  <link name="one_tool_wrist_shaft_link">
    <visual>
      <origin rpy="1.5708 0 0" xyz="0 0.00401 0"/>
      <geometry>
        <mesh filename="package://dvrk_model/meshes/psm/tool_wrist_shaft_link.dae"/>
      </geometry>
    </visual>
    <inertial>
      <origin rpy="0 0 0" xyz="0 0 0"/>
      <mass value="0.1"/>
      <inertia ixx="0.1" ixy="0.0" ixz="0.0" iyy="0.1" iyz="0.0" izz="0.005"/>
    </inertial>
  </link>
  <transmission name="one_tran1">
    <type>transmission_interface/SimpleTransmission</type>
    <joint name="one_outer_yaw_joint">
      <hardwareInterface>EffortJointInterface</hardwareInterface>
    </joint>
    <actuator name="one_motor1">
      <hardwareInterface>EffortJointInterface</hardwareInterface>
      <mechanicalReduction>1</mechanicalReduction>
    </actuator>
  </transmission>
  <transmission name="one_tran2">
    <type>transmission_interface/SimpleTransmission</type>
    <joint name="one_outer_pitch_joint">
      <hardwareInterface>EffortJointInterface</hardwareInterface>
    </joint>
    <actuator name="one_motor2">
      <hardwareInterface>EffortJointInterface</hardwareInterface>
      <mechanicalReduction>1</mechanicalReduction>
    </actuator>
  </transmission>
  <transmission name="one_tran2_1">
    <type>transmission_interface/SimpleTransmission</type>
    <joint name="one_outer_pitch_joint_1">
      <hardwareInterface>EffortJointInterface</hardwareInterface>
    </joint>
    <actuator name="one_motor2_1">
      <hardwareInterface>EffortJointInterface</hardwareInterface>
      <mechanicalReduction>1</mechanicalReduction>
    </actuator>
  </transmission>
  <transmission name="one_tran2_2">
    <type>transmission_interface/SimpleTransmission</type>
    <joint name="one_outer_pitch_joint_2">
      <hardwareInterface>EffortJointInterface</hardwareInterface>
    </joint>
    <actuator name="one_motor2_2">
      <hardwareInterface>EffortJointInterface</hardwareInterface>
      <mechanicalReduction>1</mechanicalReduction>
    </actuator>
  </transmission>
  <transmission name="one_tran2_3">
    <type>transmission_interface/SimpleTransmission</type>
    <joint name="one_outer_pitch_joint_3">
      <hardwareInterface>EffortJointInterface</hardwareInterface>
    </joint>
    <actuator name="one_motor2_3">
      <hardwareInterface>EffortJointInterface</hardwareInterface>
      <mechanicalReduction>-1</mechanicalReduction>
    </actuator>
  </transmission>
  <transmission name="one_tran2_4">
    <type>transmission_interface/SimpleTransmission</type>
    <joint name="one_outer_pitch_joint_4">
      <hardwareInterface>EffortJointInterface</hardwareInterface>
    </joint>
    <actuator name="one_motor2_4">
      <hardwareInterface>EffortJointInterface</hardwareInterface>
      <mechanicalReduction>-1</mechanicalReduction>
    </actuator>
  </transmission>
  <transmission name="one_tran2_5">
    <type>transmission_interface/SimpleTransmission</type>
    <joint name="one_outer_pitch_joint_5">
      <hardwareInterface>EffortJointInterface</hardwareInterface>
    </joint>
    <actuator name="one_motor2_5">
      <hardwareInterface>EffortJointInterface</hardwareInterface>
      <mechanicalReduction>1</mechanicalReduction>
    </actuator>
  </transmission>
  <transmission name="one_tran3">
    <type>transmission_interface/SimpleTransmission</type>
    <joint name="one_outer_insertion_joint">
      <hardwareInterface>EffortJointInterface</hardwareInterface>
    </joint>
    <actuator name="one_motor3">
      <hardwareInterface>EffortJointInterface</hardwareInterface>
      <mechanicalReduction>1</mechanicalReduction>
    </actuator>
  </transmission>
  <transmission name="one_tran4">
    <type>transmission_interface/SimpleTransmission</type>
    <joint name="one_outer_roll_joint">
      <hardwareInterface>EffortJointInterface</hardwareInterface>
    </joint>
    <actuator name="one_motor4">
      <hardwareInterface>EffortJointInterface</hardwareInterface>
      <mechanicalReduction>1</mechanicalReduction>
    </actuator>
  </transmission>
  <!-- joint 5: Outer wrist pitch joint -->
  <joint name="one_outer_wrist_pitch_joint" type="revolute">
    <parent link="one_tool_wrist_shaft_link"/>
    <child link="one_tool_wrist_sca_link"/>
    <axis xyz="0 0 1"/>
    <origin rpy="-1.5708 -1.5708 0" xyz="0 0 0"/>
    <limit effort="1000" lower="-1.5707" upper="1.5707" velocity=".4"/>
  </joint>
  <!-- link 5: tool_wrist_sca_link -->
  <!-- wsn: want to have collision properties for this -->
  <link name="one_tool_wrist_sca_link">
    <visual>
      <!-- <origin rpy="0 3.1416 0" xyz="0 0 0"/> -->
      <origin rpy="1.5708 3.1416 0" xyz="0.0051 0.0032 0"/>
      <geometry>
        <mesh filename="package://dvrk_model/meshes/psm/tool_wrist_sca_link.dae"/>
      </geometry>
    </visual>
    <collision>
      <origin rpy="1.5708 3.1416 0" xyz="0.0051 0.0032 0"/>
      <geometry>
        <!-- coarse model; a simple box -->
        <!--box size="0.05 0.2 0.05"/-->
        <mesh filename="package://dvrk_model/meshes/psm/tool_wrist_sca_link.dae"/>
      </geometry>
    </collision>
    <selfCollide>false</selfCollide>
    <inertial>
      <origin rpy="0 0 0" xyz="0 0 0"/>
      <mass value="0.05"/>
      <inertia ixx="0.01" ixy="0.0" ixz="0.0" iyy="0.01" iyz="0.0" izz="0.005"/>
    </inertial>
  </link>
  <!-- joint 6: Outer wrist yaw joint -->
  <joint name="one_outer_wrist_yaw_joint" type="revolute">
    <parent link="one_tool_wrist_sca_link"/>
    <child link="one_tool_wrist_sca_shaft_link"/>
    <axis xyz="0 0 1"/>
    <origin rpy="-1.5708 -1.5708 0" xyz="0.0091 0 0"/>
    <!-- +/- 80 deg -->
    <limit effort="1000" lower="-1.3963" upper="1.3963" velocity=".4"/>
  </joint>
  <!-- link 6: tool_wrist_sca_shaft_link -->
  <link name="one_tool_wrist_sca_shaft_link">
    <visual>
      <origin rpy="0 0 0" xyz="0 -0.0002 -0.0025"/>
      <geometry>
        <mesh filename="package://dvrk_model/meshes/psm/tool_wrist_sca_shaft_link.dae"/>
      </geometry>
    </visual>
    <inertial>
      <origin rpy="0 0 0" xyz="0 0 0"/>
      <mass value="0.05"/>
      <inertia ixx="0.01" ixy="0.0" ixz="0.0" iyy="0.01" iyz="0.0" izz="0.005"/>
    </inertial>
  </link>
  <!-- joint 7-1: Outer open angle 1  -->
  <joint name="one_outer_wrist_open_angle_joint" type="revolute">
    <parent link="one_tool_wrist_sca_shaft_link"/>
    <child link="one_tool_wrist_sca_ee_link_1"/>
    <axis xyz="0 0 1"/>
    <origin rpy="0 0 0" xyz="0 0 0"/>
    <limit effort="1000" lower="0" upper="1.5707" velocity=".4"/>
  </joint>
  <!-- link 7-1: Outer open angle link 1 -->
  <link name="one_tool_wrist_sca_ee_link_1">
    <visual>
      <origin rpy="0 0 0" xyz="0 0 0"/>
      <geometry>
        <mesh filename="package://dvrk_model/meshes/psm/tool_wrist_sca_link_2.dae"/>
      </geometry>
    </visual>
    <inertial>
      <origin rpy="0 0 0" xyz="0 0 0"/>
      <mass value="0.05"/>
      <inertia ixx="0.01" ixy="0.0" ixz="0.0" iyy="0.01" iyz="0.0" izz="0.005"/>
    </inertial>
  </link>
  <!-- joint 7-2: Outer open angle 2   -->
  <joint name="one_outer_wrist_open_angle_joint_mimic" type="revolute">
    <parent link="one_tool_wrist_sca_shaft_link"/>
    <child link="one_tool_wrist_sca_ee_link_2"/>
    <axis xyz="0 0 1"/>
    <origin rpy="0 0 0" xyz="0 0 0"/>
    <limit effort="1000" lower="-1.5707" upper="1.5707" velocity=".4"/>
    <!--mimic joint="${prefix}outer_wrist_open_angle_joint" multiplier="-1"/-->
  </joint>
  <!-- link 7-2: Outer open angle link 2 -->
  <link name="one_tool_wrist_sca_ee_link_2">
    <visual>
      <origin rpy="0 3.1516 0" xyz="0 0 0"/>
      <geometry>
        <mesh filename="package://dvrk_model/meshes/psm/tool_wrist_sca_link_2.dae"/>
      </geometry>
    </visual>
    <inertial>
      <origin rpy="0 0 0" xyz="0 0 0"/>
      <mass value="0.05"/>
      <inertia ixx="0.01" ixy="0.0" ixz="0.0" iyy="0.01" iyz="0.0" izz="0.005"/>
    </inertial>
  </link>
  <!-- wsn: try adding a fingertip for grasping -->
  <link name="one_fingertip2">
    <visual>
      <origin rpy="0 0 0" xyz="0.001 0.005 0.0005"/>
      <geometry>
        <box size="0.002 0.01 0.004"/>
      </geometry>
    </visual>
    <collision>
      <origin rpy="0 0 0" xyz="0.001 0.005 0.0005"/>
      <geometry>
        <box size="0.002 0.01 0.004"/>
      </geometry>
      <surface>
        <friction>
          <ode>
            <mu>30.0</mu>
            <mu2>30.0</mu2>
          </ode>
        </friction>
        <contact>
          <ode>
            <kp>1000000.0</kp>
            <kd>100.0</kd>
            <max_vel>1.0</max_vel>
            <min_depth>0.001</min_depth>
          </ode>
        </contact>
      </surface>
    </collision>
    <inertial>
      <origin rpy="0 0 0" xyz="0 0 0"/>
      <mass value="0.05"/>
      <inertia ixx="0.01" ixy="0.0" ixz="0.0" iyy="0.01" iyz="0.0" izz="0.005"/>
    </inertial>
  </link>
  <!-- attach fingertip pad  -->
  <joint name="one_fingertip2_joint" type="fixed">
    <parent link="one_tool_wrist_sca_ee_link_2"/>
    <child link="one_fingertip2"/>
    <axis xyz="0 0 1"/>
    <origin rpy="0 0 0" xyz="0 0 0"/>
  </joint>
  <!-- wsn: other fingertip -->
  <link name="one_fingertip1">
    <visual>
      <origin rpy="0 0 0" xyz="-0.001 0.005 0.0005"/>
      <geometry>
        <box size="0.002 0.01 0.004"/>
      </geometry>
    </visual>
    <collision>
      <origin rpy="0 0 0" xyz="-0.001 0.005 0.0005"/>
      <geometry>
        <box size="0.002 0.01 0.004"/>
      </geometry>
      <surface>
        <friction>
          <ode>
            <mu>30.0</mu>
            <mu2>30.0</mu2>
          </ode>
        </friction>
        <contact>
          <ode>
            <kp>1000000.0</kp>
            <kd>100.0</kd>
            <max_vel>1.0</max_vel>
            <min_depth>0.001</min_depth>
          </ode>
        </contact>
      </surface>
    </collision>
    <inertial>
      <origin rpy="0 0 0" xyz="0 0 0"/>
      <mass value="0.05"/>
      <inertia ixx="0.01" ixy="0.0" ixz="0.0" iyy="0.01" iyz="0.0" izz="0.005"/>
    </inertial>
  </link>
  <!-- attach fingertip pad 1  -->
  <joint name="one_fingertip1_joint" type="fixed">
    <parent link="one_tool_wrist_sca_ee_link_1"/>
    <child link="one_fingertip1"/>
    <axis xyz="0 0 1"/>
    <origin rpy="0 0 0" xyz="0 0 0"/>
  </joint>
  <!-- tool tip -->
  <joint name="one_tool_tip_joint_" type="fixed">
    <parent link="one_tool_wrist_sca_shaft_link"/>
    <child link="one_tool_tip_link"/>
    <origin rpy="0 1.57079632679 1.57079632679" xyz="0 0.0102 0"/>
  </joint>
  <link name="one_tool_tip_link">
    <visual>
      <geometry>
        <!-- put a fiducial, a sphere, at the tool tips -->
        <sphere radius="0.001"/>
      </geometry>
    </visual>
  </link>
  <!--this colors the tool-tip fiducial red; oddly, this shows up in the camera view, but NOT in the rviz view -->
  <gazebo reference="one_tool_tip_link">
    <material>Gazebo/Red</material>
  </gazebo>
  <transmission name="one_tran5">
    <type>transmission_interface/SimpleTransmission</type>
    <joint name="one_outer_wrist_pitch_joint">
      <hardwareInterface>EffortJointInterface</hardwareInterface>
    </joint>
    <actuator name="one_motor5">
      <hardwareInterface>EffortJointInterface</hardwareInterface>
      <mechanicalReduction>1</mechanicalReduction>
    </actuator>
  </transmission>
  <transmission name="one_tran6">
    <type>transmission_interface/SimpleTransmission</type>
    <joint name="one_outer_wrist_yaw_joint">
      <hardwareInterface>EffortJointInterface</hardwareInterface>
    </joint>
    <actuator name="one_motor6">
      <hardwareInterface>EffortJointInterface</hardwareInterface>
      <mechanicalReduction>1</mechanicalReduction>
    </actuator>
  </transmission>
  <transmission name="one_tran7">
    <type>transmission_interface/SimpleTransmission</type>
    <joint name="one_outer_wrist_open_angle_joint">
      <hardwareInterface>EffortJointInterface</hardwareInterface>
    </joint>
    <actuator name="one_motor7">
      <hardwareInterface>EffortJointInterface</hardwareInterface>
      <mechanicalReduction>1</mechanicalReduction>
    </actuator>
  </transmission>
  <transmission name="one_tran7_mimic">
    <type>transmission_interface/SimpleTransmission</type>
    <joint name="one_outer_wrist_open_angle_joint_mimic">
      <hardwareInterface>EffortJointInterface</hardwareInterface>
    </joint>
    <actuator name="one_motor7_mimic">
      <hardwareInterface>EffortJointInterface</hardwareInterface>
      <mechanicalReduction>1</mechanicalReduction>
    </actuator>
  </transmission>
  <!-- fixed joint -->
  <joint name="two_fixed_joint" type="fixed">
    <parent link="camera"/>
    <child link="two_psm_base_link"/>
    <origin rpy="0.0 0.0 3.1415926" xyz="0.15 0.05 0.5"/>
  </joint>
  <!-- link 0: psm base link -->
  <link name="two_psm_base_link">
    <visual>
      <origin rpy="1.5708 0 3.1416" xyz="0.039 -0.40788 -0.07879"/>
      <geometry>
        <mesh filename="package://dvrk_model/meshes/psm/psm_base.dae"/>
      </geometry>
    </visual>
    <inertial>
      <origin rpy="0 0 0" xyz="0 0 0"/>
      <mass value="1"/>
      <inertia ixx="0.1" ixy="0.0" ixz="0.0" iyy="0.1" iyz="0.0" izz="0.1"/>
    </inertial>
  </link>
  <!-- joint 1 -->
  <joint name="two_outer_yaw_joint" type="revolute">
    <parent link="two_psm_base_link"/>
    <child link="two_outer_yaw_link"/>
    <axis xyz="0 0 1"/>
    <!-- <origin rpy="1.5708 -1.5708 0" xyz="0.0 -0.369 0.0"/> -->
    <origin rpy="0 -1.5708 1.5708" xyz="0.0 0.0 0.0"/>
    <dynamics damping="1"/>
    <limit effort="1000" lower="-1.5707" upper="1.5707" velocity=".4"/>
  </joint>
  <!-- link 1: outer_yaw -->
  <link name="two_outer_yaw_link">
    <visual>
      <!-- <origin rpy="0 0 -1.5708" xyz="0.0125 0 0.1575"/> -->
      <origin rpy="3.1416 0 1.5708" xyz="0.0125 0 0.5265"/>
      <geometry>
        <mesh filename="package://dvrk_model/meshes/psm/outer_yaw.dae"/>
      </geometry>
    </visual>
    <inertial>
      <origin rpy="0 0 0" xyz="0 0 0"/>
      <mass value="0.1"/>
      <inertia ixx="0.1" ixy="0.0" ixz="0.0" iyy="0.1" iyz="0.0" izz="0.005"/>
    </inertial>
  </link>
  <!-- Note: I can not put visual link here as it's parallel -->
  <!-- mechanism, so the outer_pitch_link does not have visual -->
  <!-- link, all visual links mimic outer_pitch_joint value -->
  <!-- joint 2: outer_pitch -->
  <joint name="two_outer_pitch_joint" type="revolute">
    <parent link="two_outer_yaw_link"/>
    <child link="two_outer_pitch_link"/>
    <axis xyz="0 0 1"/>
    <origin rpy="-1.5708 -1.5708 0" xyz="0 0 0"/>
    <dynamics damping="1"/>
    <limit effort="1000" lower="-0.7854" upper="0.7854" velocity=".4"/>
  </joint>
  <!-- link 2: outer_pitch_link -->
  <link name="two_outer_pitch_link">
    <inertial>
      <origin rpy="0 0 0" xyz="0 0 0"/>
      <mass value="0.1"/>
      <inertia ixx="0.1" ixy="0.0" ixz="0.0" iyy="0.1" iyz="0.0" izz="0.005"/>
    </inertial>
  </link>
  <!--wsn: for visualization links/joints of closed-chain mechanism, assign dynamic properties and control w/ fdbk-->
  <!-- joint 2-1: outer_pitch_1 -->
  <joint name="two_outer_pitch_joint_1" type="continuous">
    <parent link="two_outer_yaw_link"/>
    <child link="two_outer_pitch_back_link"/>
    <axis xyz="0 0 1"/>
    <!-- <origin rpy="-1.5708 -1.5708 0" xyz="0 0.0295 0.1495"/> -->
    <dynamics damping="1"/>
    <origin rpy="-1.5708 -1.5708 0" xyz="0 0.0295 0.5185"/>
    <!--mimic joint="${prefix}outer_pitch_joint" multiplier="1"/-->
    <limit effort="1000" lower="-0.7854" upper="0.7854" velocity=".4"/>
  </joint>
  <!-- link 2-1: outer_pitch_back -->
  <link name="two_outer_pitch_back_link">
    <visual>
      <origin rpy="0 0 -0.27129" xyz="0 0 0"/>
      <geometry>
        <mesh filename="package://dvrk_model/meshes/psm/outer_pitch_back.dae"/>
      </geometry>
    </visual>
    <inertial>
      <origin rpy="0 0 0" xyz="0 0 0"/>
      <mass value="0.1"/>
      <inertia ixx="0.1" ixy="0.0" ixz="0.0" iyy="0.1" iyz="0.0" izz="0.005"/>
    </inertial>
  </link>
  <!-- joint 2-2: outer_pitch_2 -->
  <joint name="two_outer_pitch_joint_2" type="continuous">
    <parent link="two_outer_yaw_link"/>
    <child link="two_outer_pitch_front_link"/>
    <axis xyz="0 0 1"/>
    <origin rpy="-1.5708 -1.5708 0" xyz="0 0.0295 0.4285"/>
    <!--mimic joint="${prefix}outer_pitch_joint" multiplier="1"/-->
    <limit effort="1000" lower="-0.7854" upper="0.7854" velocity=".4"/>
    <dynamics damping="1"/>
  </joint>
  <!-- link 2-2: outer_pitch_front -->
  <link name="two_outer_pitch_front_link">
    <visual>
      <origin rpy="0 0 -0.27129" xyz="0 0 0"/>
      <geometry>
        <mesh filename="package://dvrk_model/meshes/psm/outer_pitch_front.dae"/>
      </geometry>
    </visual>
    <inertial>
      <origin rpy="0 0 0" xyz="0 0 0"/>
      <mass value="0.1"/>
      <inertia ixx="0.1" ixy="0.0" ixz="0.0" iyy="0.1" iyz="0.0" izz="0.005"/>
    </inertial>
  </link>
  <!-- joint 2-3: outer_pitch_3 -->
  <joint name="two_outer_pitch_joint_3" type="continuous">
    <parent link="two_outer_pitch_back_link"/>
    <child link="two_outer_pitch_bottom_link"/>
    <axis xyz="0 0 1"/>
    <origin rpy="0 0 0" xyz="0.04178 0.15007 -0.0137"/>
    <origin rpy="0 0 0" xyz="0.04178 0.15007 -0.0137"/>
    <!--mimic joint="outer_pitch_joint" multiplier="-1"/-->
    <dynamics damping="1"/>
  </joint>
  <!-- link 2-3: outer_pitch_bottom -->
  <link name="two_outer_pitch_bottom_link">
    <visual>
      <origin rpy="0 -1.5708 0" xyz="0.009 0 0"/>
      <geometry>
        <mesh filename="package://dvrk_model/meshes/psm/outer_pitch_bottom.dae"/>
      </geometry>
    </visual>
    <inertial>
      <origin rpy="0 0 0" xyz="0 0 0"/>
      <mass value="0.1"/>
      <inertia ixx="0.1" ixy="0.0" ixz="0.0" iyy="0.1" iyz="0.0" izz="0.005"/>
    </inertial>
  </link>
  <!-- joint 2-4: outer_pitch_4 -->
  <joint name="two_outer_pitch_joint_4" type="continuous">
    <parent link="two_outer_pitch_back_link"/>
    <child link="two_outer_pitch_top_link"/>
    <axis xyz="0 0 1"/>
    <origin rpy="0 0 0" xyz="0.04209 0.18695 -0.02412"/>
    <!--mimic joint="${prefix}outer_pitch_joint" multiplier="-1"/-->
    <limit effort="1000" lower="-0.7854" upper="0.7854" velocity=".4"/>
    <dynamics damping="1"/>
  </joint>
  <!-- link 2-4: outer_pitch_top -->
  <link name="two_outer_pitch_top_link">
    <visual>
      <origin rpy="0 -1.5708 0" xyz="0.009 0 0"/>
      <geometry>
        <mesh filename="package://dvrk_model/meshes/psm/outer_pitch_top.dae"/>
      </geometry>
    </visual>
    <inertial>
      <origin rpy="0 0 0" xyz="0 0 0"/>
      <mass value="0.1"/>
      <inertia ixx="0.1" ixy="0.0" ixz="0.0" iyy="0.1" iyz="0.0" izz="0.005"/>
    </inertial>
  </link>
  <!-- joint 2-5: outer_pitch_5 -->
  <joint name="two_outer_pitch_joint_5" type="continuous">
    <parent link="two_outer_pitch_bottom_link"/>
    <child link="two_outer_insertion_link"/>
    <axis xyz="0 0 1"/>
    <origin rpy="0 0 0" xyz="-0.520 0 -0.0155"/>
    <!--mimic joint="${prefix}outer_pitch_joint" multiplier="1"/-->
    <limit effort="1000" lower="-0.7854" upper="0.7854" velocity=".4"/>
    <dynamics damping="1"/>
  </joint>
  <!-- link 2-5: outer_insertion -->
  <link name="two_outer_insertion_link">
    <visual>
      <origin rpy="0 -1.5708 1.5708" xyz="0.02528 0.429 0"/>
      <geometry>
        <mesh filename="package://dvrk_model/meshes/psm/outer_insertion.dae"/>
      </geometry>
    </visual>
    <inertial>
      <origin rpy="0 0 0" xyz="0 0 0"/>
      <mass value="0.1"/>
      <inertia ixx="0.1" ixy="0.0" ixz="0.0" iyy="0.1" iyz="0.0" izz="0.005"/>
    </inertial>
  </link>
  <!-- joint 3: insertion -->
  <joint name="two_outer_insertion_joint" type="prismatic">
    <!-- <parent link="${prefix}outer_insertion_link"/> -->
    <!-- <parent link="${prefix}psm_base_link"/> -->
    <parent link="two_outer_pitch_link"/>
    <child link="two_tool_main_link"/>
    <axis xyz="0 0 1"/>
    <origin rpy="1.5708 0 0" xyz="0 0.4318 0"/>
    <limit effort="1000" lower="0" upper="0.240" velocity=".4"/>
    <dynamics damping="1"/>
  </joint>
  <!-- link 3: tool_main_link -->
  <link name="two_tool_main_link">
    <visual>
      <origin rpy="0 0 1.5708" xyz="0 0 0.041"/>
      <geometry>
        <mesh filename="package://dvrk_model/meshes/psm/tool_main.dae"/>
      </geometry>
    </visual>
    <inertial>
      <origin rpy="0 0 0" xyz="0 0 0"/>
      <mass value="0.1"/>
      <inertia ixx="0.1" ixy="0.0" ixz="0.0" iyy="0.1" iyz="0.0" izz="0.005"/>
    </inertial>
  </link>
  <!-- joint 4: Outer Roll -->
  <joint name="two_outer_roll_joint" type="revolute">
    <parent link="two_tool_main_link"/>
    <child link="two_tool_wrist_link"/>
    <axis xyz="0 0 1"/>
    <origin rpy="0 0 0" xyz="0 0 0.4162"/>
    <limit effort="1000" lower="-2.2689" upper="2.2689" velocity=".4"/>
    <dynamics damping="1"/>
  </joint>
  <!-- link 4: tool_wrist_link -->
  <link name="two_tool_wrist_link">
    <visual>
      <origin rpy="0 0 1.5708" xyz="0 0 -0.0091"/>
      <geometry>
        <mesh filename="package://dvrk_model/meshes/psm/tool_wrist_link.dae"/>
      </geometry>
    </visual>
    <inertial>
      <origin rpy="0 0 0" xyz="0 0 0"/>
      <mass value="0.1"/>
      <inertia ixx="0.1" ixy="0.0" ixz="0.0" iyy="0.1" iyz="0.0" izz="0.005"/>
    </inertial>
  </link>
  <!-- joint 4-1: outer roll shaft joint FIXED-->
  <joint name="two_outer_roll_shaft_joint" type="fixed">
    <parent link="two_tool_wrist_link"/>
    <child link="two_tool_wrist_shaft_link"/>
    <axis xyz="0 0 1"/>
    <origin rpy="0 0 0" xyz="0 0 0.0"/>
  </joint>
  <!-- link 4-1: tool_wrist_shaft_link -->
  <link name="two_tool_wrist_shaft_link">
    <visual>
      <origin rpy="1.5708 0 0" xyz="0 0.00401 0"/>
      <geometry>
        <mesh filename="package://dvrk_model/meshes/psm/tool_wrist_shaft_link.dae"/>
      </geometry>
    </visual>
    <inertial>
      <origin rpy="0 0 0" xyz="0 0 0"/>
      <mass value="0.1"/>
      <inertia ixx="0.1" ixy="0.0" ixz="0.0" iyy="0.1" iyz="0.0" izz="0.005"/>
    </inertial>
  </link>
  <transmission name="two_tran1">
    <type>transmission_interface/SimpleTransmission</type>
    <joint name="two_outer_yaw_joint">
      <hardwareInterface>EffortJointInterface</hardwareInterface>
    </joint>
    <actuator name="two_motor1">
      <hardwareInterface>EffortJointInterface</hardwareInterface>
      <mechanicalReduction>1</mechanicalReduction>
    </actuator>
  </transmission>
  <transmission name="two_tran2">
    <type>transmission_interface/SimpleTransmission</type>
    <joint name="two_outer_pitch_joint">
      <hardwareInterface>EffortJointInterface</hardwareInterface>
    </joint>
    <actuator name="two_motor2">
      <hardwareInterface>EffortJointInterface</hardwareInterface>
      <mechanicalReduction>1</mechanicalReduction>
    </actuator>
  </transmission>
  <transmission name="two_tran2_1">
    <type>transmission_interface/SimpleTransmission</type>
    <joint name="two_outer_pitch_joint_1">
      <hardwareInterface>EffortJointInterface</hardwareInterface>
    </joint>
    <actuator name="two_motor2_1">
      <hardwareInterface>EffortJointInterface</hardwareInterface>
      <mechanicalReduction>1</mechanicalReduction>
    </actuator>
  </transmission>
  <transmission name="two_tran2_2">
    <type>transmission_interface/SimpleTransmission</type>
    <joint name="two_outer_pitch_joint_2">
      <hardwareInterface>EffortJointInterface</hardwareInterface>
    </joint>
    <actuator name="two_motor2_2">
      <hardwareInterface>EffortJointInterface</hardwareInterface>
      <mechanicalReduction>1</mechanicalReduction>
    </actuator>
  </transmission>
  <transmission name="two_tran2_3">
    <type>transmission_interface/SimpleTransmission</type>
    <joint name="two_outer_pitch_joint_3">
      <hardwareInterface>EffortJointInterface</hardwareInterface>
    </joint>
    <actuator name="two_motor2_3">
      <hardwareInterface>EffortJointInterface</hardwareInterface>
      <mechanicalReduction>-1</mechanicalReduction>
    </actuator>
  </transmission>
  <transmission name="two_tran2_4">
    <type>transmission_interface/SimpleTransmission</type>
    <joint name="two_outer_pitch_joint_4">
      <hardwareInterface>EffortJointInterface</hardwareInterface>
    </joint>
    <actuator name="two_motor2_4">
      <hardwareInterface>EffortJointInterface</hardwareInterface>
      <mechanicalReduction>-1</mechanicalReduction>
    </actuator>
  </transmission>
  <transmission name="two_tran2_5">
    <type>transmission_interface/SimpleTransmission</type>
    <joint name="two_outer_pitch_joint_5">
      <hardwareInterface>EffortJointInterface</hardwareInterface>
    </joint>
    <actuator name="two_motor2_5">
      <hardwareInterface>EffortJointInterface</hardwareInterface>
      <mechanicalReduction>1</mechanicalReduction>
    </actuator>
  </transmission>
  <transmission name="two_tran3">
    <type>transmission_interface/SimpleTransmission</type>
    <joint name="two_outer_insertion_joint">
      <hardwareInterface>EffortJointInterface</hardwareInterface>
    </joint>
    <actuator name="two_motor3">
      <hardwareInterface>EffortJointInterface</hardwareInterface>
      <mechanicalReduction>1</mechanicalReduction>
    </actuator>
  </transmission>
  <transmission name="two_tran4">
    <type>transmission_interface/SimpleTransmission</type>
    <joint name="two_outer_roll_joint">
      <hardwareInterface>EffortJointInterface</hardwareInterface>
    </joint>
    <actuator name="two_motor4">
      <hardwareInterface>EffortJointInterface</hardwareInterface>
      <mechanicalReduction>1</mechanicalReduction>
    </actuator>
  </transmission>
  <!-- joint 5: Outer wrist pitch joint -->
  <joint name="two_outer_wrist_pitch_joint" type="revolute">
    <parent link="two_tool_wrist_shaft_link"/>
    <child link="two_tool_wrist_sca_link"/>
    <axis xyz="0 0 1"/>
    <origin rpy="-1.5708 -1.5708 0" xyz="0 0 0"/>
    <limit effort="1000" lower="-1.5707" upper="1.5707" velocity=".4"/>
  </joint>
  <!-- link 5: tool_wrist_sca_link -->
  <!-- wsn: want to have collision properties for this -->
  <link name="two_tool_wrist_sca_link">
    <visual>
      <!-- <origin rpy="0 3.1416 0" xyz="0 0 0"/> -->
      <origin rpy="1.5708 3.1416 0" xyz="0.0051 0.0032 0"/>
      <geometry>
        <mesh filename="package://dvrk_model/meshes/psm/tool_wrist_sca_link.dae"/>
      </geometry>
    </visual>
    <collision>
      <origin rpy="1.5708 3.1416 0" xyz="0.0051 0.0032 0"/>
      <geometry>
        <!-- coarse model; a simple box -->
        <!--box size="0.05 0.2 0.05"/-->
        <mesh filename="package://dvrk_model/meshes/psm/tool_wrist_sca_link.dae"/>
      </geometry>
    </collision>
    <selfCollide>false</selfCollide>
    <inertial>
      <origin rpy="0 0 0" xyz="0 0 0"/>
      <mass value="0.05"/>
      <inertia ixx="0.01" ixy="0.0" ixz="0.0" iyy="0.01" iyz="0.0" izz="0.005"/>
    </inertial>
  </link>
  <!-- joint 6: Outer wrist yaw joint -->
  <joint name="two_outer_wrist_yaw_joint" type="revolute">
    <parent link="two_tool_wrist_sca_link"/>
    <child link="two_tool_wrist_sca_shaft_link"/>
    <axis xyz="0 0 1"/>
    <origin rpy="-1.5708 -1.5708 0" xyz="0.0091 0 0"/>
    <!-- +/- 80 deg -->
    <limit effort="1000" lower="-1.3963" upper="1.3963" velocity=".4"/>
  </joint>
  <!-- link 6: tool_wrist_sca_shaft_link -->
  <link name="two_tool_wrist_sca_shaft_link">
    <visual>
      <origin rpy="0 0 0" xyz="0 -0.0002 -0.0025"/>
      <geometry>
        <mesh filename="package://dvrk_model/meshes/psm/tool_wrist_sca_shaft_link.dae"/>
      </geometry>
    </visual>
    <inertial>
      <origin rpy="0 0 0" xyz="0 0 0"/>
      <mass value="0.05"/>
      <inertia ixx="0.01" ixy="0.0" ixz="0.0" iyy="0.01" iyz="0.0" izz="0.005"/>
    </inertial>
  </link>
  <!-- joint 7-1: Outer open angle 1  -->
  <joint name="two_outer_wrist_open_angle_joint" type="revolute">
    <parent link="two_tool_wrist_sca_shaft_link"/>
    <child link="two_tool_wrist_sca_ee_link_1"/>
    <axis xyz="0 0 1"/>
    <origin rpy="0 0 0" xyz="0 0 0"/>
    <limit effort="1000" lower="0" upper="1.5707" velocity=".4"/>
  </joint>
  <!-- link 7-1: Outer open angle link 1 -->
  <link name="two_tool_wrist_sca_ee_link_1">
    <visual>
      <origin rpy="0 0 0" xyz="0 0 0"/>
      <geometry>
        <mesh filename="package://dvrk_model/meshes/psm/tool_wrist_sca_link_2.dae"/>
      </geometry>
    </visual>
    <inertial>
      <origin rpy="0 0 0" xyz="0 0 0"/>
      <mass value="0.05"/>
      <inertia ixx="0.01" ixy="0.0" ixz="0.0" iyy="0.01" iyz="0.0" izz="0.005"/>
    </inertial>
  </link>
  <!-- joint 7-2: Outer open angle 2   -->
  <joint name="two_outer_wrist_open_angle_joint_mimic" type="revolute">
    <parent link="two_tool_wrist_sca_shaft_link"/>
    <child link="two_tool_wrist_sca_ee_link_2"/>
    <axis xyz="0 0 1"/>
    <origin rpy="0 0 0" xyz="0 0 0"/>
    <limit effort="1000" lower="-1.5707" upper="1.5707" velocity=".4"/>
    <!--mimic joint="${prefix}outer_wrist_open_angle_joint" multiplier="-1"/-->
  </joint>
  <!-- link 7-2: Outer open angle link 2 -->
  <link name="two_tool_wrist_sca_ee_link_2">
    <visual>
      <origin rpy="0 3.1516 0" xyz="0 0 0"/>
      <geometry>
        <mesh filename="package://dvrk_model/meshes/psm/tool_wrist_sca_link_2.dae"/>
      </geometry>
    </visual>
    <inertial>
      <origin rpy="0 0 0" xyz="0 0 0"/>
      <mass value="0.05"/>
      <inertia ixx="0.01" ixy="0.0" ixz="0.0" iyy="0.01" iyz="0.0" izz="0.005"/>
    </inertial>
  </link>
  <!-- wsn: try adding a fingertip for grasping -->
  <link name="two_fingertip2">
    <visual>
      <origin rpy="0 0 0" xyz="0.001 0.005 0.0005"/>
      <geometry>
        <box size="0.002 0.01 0.004"/>
      </geometry>
    </visual>
    <collision>
      <origin rpy="0 0 0" xyz="0.001 0.005 0.0005"/>
      <geometry>
        <box size="0.002 0.01 0.004"/>
      </geometry>
      <surface>
        <friction>
          <ode>
            <mu>30.0</mu>
            <mu2>30.0</mu2>
          </ode>
        </friction>
        <contact>
          <ode>
            <kp>1000000.0</kp>
            <kd>100.0</kd>
            <max_vel>1.0</max_vel>
            <min_depth>0.001</min_depth>
          </ode>
        </contact>
      </surface>
    </collision>
    <inertial>
      <origin rpy="0 0 0" xyz="0 0 0"/>
      <mass value="0.05"/>
      <inertia ixx="0.01" ixy="0.0" ixz="0.0" iyy="0.01" iyz="0.0" izz="0.005"/>
    </inertial>
  </link>
  <!-- attach fingertip pad  -->
  <joint name="two_fingertip2_joint" type="fixed">
    <parent link="two_tool_wrist_sca_ee_link_2"/>
    <child link="two_fingertip2"/>
    <axis xyz="0 0 1"/>
    <origin rpy="0 0 0" xyz="0 0 0"/>
  </joint>
  <!-- wsn: other fingertip -->
  <link name="two_fingertip1">
    <visual>
      <origin rpy="0 0 0" xyz="-0.001 0.005 0.0005"/>
      <geometry>
        <box size="0.002 0.01 0.004"/>
      </geometry>
    </visual>
    <collision>
      <origin rpy="0 0 0" xyz="-0.001 0.005 0.0005"/>
      <geometry>
        <box size="0.002 0.01 0.004"/>
      </geometry>
      <surface>
        <friction>
          <ode>
            <mu>30.0</mu>
            <mu2>30.0</mu2>
          </ode>
        </friction>
        <contact>
          <ode>
            <kp>1000000.0</kp>
            <kd>100.0</kd>
            <max_vel>1.0</max_vel>
            <min_depth>0.001</min_depth>
          </ode>
        </contact>
      </surface>
    </collision>
    <inertial>
      <origin rpy="0 0 0" xyz="0 0 0"/>
      <mass value="0.05"/>
      <inertia ixx="0.01" ixy="0.0" ixz="0.0" iyy="0.01" iyz="0.0" izz="0.005"/>
    </inertial>
  </link>
  <!-- attach fingertip pad 1  -->
  <joint name="two_fingertip1_joint" type="fixed">
    <parent link="two_tool_wrist_sca_ee_link_1"/>
    <child link="two_fingertip1"/>
    <axis xyz="0 0 1"/>
    <origin rpy="0 0 0" xyz="0 0 0"/>
  </joint>
  <!-- tool tip -->
  <joint name="two_tool_tip_joint_" type="fixed">
    <parent link="two_tool_wrist_sca_shaft_link"/>
    <child link="two_tool_tip_link"/>
    <origin rpy="0 1.57079632679 1.57079632679" xyz="0 0.0102 0"/>
  </joint>
  <link name="two_tool_tip_link">
    <visual>
      <geometry>
        <!-- put a fiducial, a sphere, at the tool tips -->
        <sphere radius="0.001"/>
      </geometry>
    </visual>
  </link>
  <!--this colors the tool-tip fiducial red; oddly, this shows up in the camera view, but NOT in the rviz view -->
  <gazebo reference="two_tool_tip_link">
    <material>Gazebo/Red</material>
  </gazebo>
  <transmission name="two_tran5">
    <type>transmission_interface/SimpleTransmission</type>
    <joint name="two_outer_wrist_pitch_joint">
      <hardwareInterface>EffortJointInterface</hardwareInterface>
    </joint>
    <actuator name="two_motor5">
      <hardwareInterface>EffortJointInterface</hardwareInterface>
      <mechanicalReduction>1</mechanicalReduction>
    </actuator>
  </transmission>
  <transmission name="two_tran6">
    <type>transmission_interface/SimpleTransmission</type>
    <joint name="two_outer_wrist_yaw_joint">
      <hardwareInterface>EffortJointInterface</hardwareInterface>
    </joint>
    <actuator name="two_motor6">
      <hardwareInterface>EffortJointInterface</hardwareInterface>
      <mechanicalReduction>1</mechanicalReduction>
    </actuator>
  </transmission>
  <transmission name="two_tran7">
    <type>transmission_interface/SimpleTransmission</type>
    <joint name="two_outer_wrist_open_angle_joint">
      <hardwareInterface>EffortJointInterface</hardwareInterface>
    </joint>
    <actuator name="two_motor7">
      <hardwareInterface>EffortJointInterface</hardwareInterface>
      <mechanicalReduction>1</mechanicalReduction>
    </actuator>
  </transmission>
  <transmission name="two_tran7_mimic">
    <type>transmission_interface/SimpleTransmission</type>
    <joint name="two_outer_wrist_open_angle_joint_mimic">
      <hardwareInterface>EffortJointInterface</hardwareInterface>
    </joint>
    <actuator name="two_motor7_mimic">
      <hardwareInterface>EffortJointInterface</hardwareInterface>
      <mechanicalReduction>1</mechanicalReduction>
    </actuator>
  </transmission>
  <!-- ros_control plugin -->
  <gazebo>
    <plugin filename="libgazebo_ros_control.so" name="gazebo_ros_control">
      <robotNamespace>/davinci</robotNamespace>
      <robotSimType>gazebo_ros_control/DefaultRobotHWSim</robotSimType>
    </plugin>
  </gazebo>
  <!-- camera -->
  <gazebo reference="right_camera_link">
    <sensor name="right_camera" type="camera">
      <update_rate>30.0</update_rate>
      <camera name="right_camera">
        <horizontal_fov>0.6</horizontal_fov>
        <image>
          <width>640</width>
          <height>480</height>
          <format>R8G8B8</format>
        </image>
        <clip>
          <near>0.005</near>
          <far>0.9</far>
        </clip>
        <noise>
          <type>gaussian</type>
          <!-- Noise is sampled independently per pixel on each frame.
               That pixel's noise value is added to each of its color
               channels, which at that point lie in the range [0,1]. -->
          <mean>0.0</mean>
          <stddev>0.007</stddev>
        </noise>
      </camera>
      <plugin filename="libgazebo_ros_camera.so" name="camera_controller">
        <alwaysOn>true</alwaysOn>
        <updateRate>0.0</updateRate>
        <cameraName>davinci/right_camera</cameraName>
        <imageTopicName>image_raw</imageTopicName>
        <cameraInfoTopicName>camera_info</cameraInfoTopicName>
        <frameName>right_camera_link</frameName>
        <hackBaseline>0.07</hackBaseline>
        <distortionK1>0.0</distortionK1>
        <distortionK2>0.0</distortionK2>
        <distortionK3>0.0</distortionK3>
        <distortionT1>0.0</distortionT1>
        <distortionT2>0.0</distortionT2>
      </plugin>
    </sensor>
  </gazebo>
  <!-- left camera -->
  <gazebo reference="left_camera_link">
    <sensor name="left_camera" type="camera">
      <update_rate>30.0</update_rate>
      <camera name="left_camera">
        <horizontal_fov>0.6</horizontal_fov>
        <image>
          <width>640</width>
          <height>480</height>
          <format>R8G8B8</format>
        </image>
        <clip>
          <near>0.005</near>
          <far>0.9</far>
        </clip>
        <noise>
          <type>gaussian</type>
          <!-- Noise is sampled independently per pixel on each frame.
               That pixel's noise value is added to each of its color
               channels, which at that point lie in the range [0,1]. -->
          <mean>0.0</mean>
          <stddev>0.007</stddev>
        </noise>
      </camera>
      <plugin filename="libgazebo_ros_camera.so" name="camera_controller">
        <alwaysOn>true</alwaysOn>
        <updateRate>0.0</updateRate>
        <cameraName>davinci/left_camera</cameraName>
        <imageTopicName>image_raw</imageTopicName>
        <cameraInfoTopicName>camera_info</cameraInfoTopicName>
        <frameName>left_camera_optical_frame</frameName>
        <!--frameName>left_camera_link</frameName-->
        <hackBaseline>0.07</hackBaseline>
        <distortionK1>0.0</distortionK1>
        <distortionK2>0.0</distortionK2>
        <distortionK3>0.0</distortionK3>
        <distortionT1>0.0</distortionT1>
        <distortionT2>0.0</distortionT2>
      </plugin>
    </sensor>
  </gazebo>
</robot>

